Workbook

Sheet database
A1: Indicator | B1: Min | C1: Max | D1: Category | E1: Rank | F1: Score | G1: ID | H1: Input Type
A2: ECe | B2: 0 | C2: 4 | D2: Very Low | E2: 5 | F2: 100 | G2: 1 | H2: Numeric
A3: ECe | B3: 4 | C3: 8 | D3: Low | E3: 4 | F3: 95 | G3: 2 | H3: Numeric
A4: ECe | B4: 8 | C4: 16 | D4: Moderate | E4: 3 | F4: 90 | G4: 3 | H4: Numeric
A5: ECe | B5: 16 | C5: 32 | D5: High | E5: 2 | F5: 85 | G5: 4 | H5: Numeric
A6: ECe | B6: 32 | C6: 999 | D6: Very High | E6: 1 | F6: 80 | G6: 5 | H6: Numeric
A7: …... | B7: ….. | C7: ….. | D7: ….. | E7: ….. | F7: ….. | G7: ….. | H7: …..
A8: soil depth | B8: 0 | C8: 25 | D8: Very Shallow | E8: 1 | F8: 50 | G8: 1 | H8: Numeric
A9: soil depth | B9: 25 | C9: 60 | D9: Shallow | E9: 2 | F9: 70 | G9: 2 | H9: Numeric
A10: soil depth | B10: 60 | C10: 90 | D10: Moderate | E10: 3 | F10: 80 | G10: 3 | H10: Numeric
A11: soil depth | B11: 90 | C11: 120 | D11: Deep | E11: 4 | F11: 90 | G11: 4 | H11: Numeric
A12: soil depth | B12: 120 | C12: 999 | D12: Very Deep | E12: 5 | F12: 100 | G12: 5 | H12: Numeric
A13: …... | B13: …... | C13: …... | D13: …... | E13: …... | F13: …... | G13: …... | H13: …...
A14: CaCO3 | B14: 0 | C14: 0 | D14: Non-Calcareous | E14: 5 | F14: 100 | G14: 1 | H14: Numeric
A15: CaCO3 | B15: 0 | C15: 2 | D15: Slightly Calcareous | E15: 4 | F15: 95 | G15: 2 | H15: Numeric
A16: CaCO3 | B16: 2 | C16: 10 | D16: Moderately Calcareous | E16: 3 | F16: 90 | G16: 3 | H16: Numeric
A17: CaCO3 | B17: 10 | C17: 25 | D17: Strongly Calcareous | E17: 2 | F17: 85 | G17: 4 | H17: Numeric
A18: CaCO3 | B18: 25 | C18: 999 | D18: Extremely Calcareous | E18: 1 | F18: 80 | G18: 5 | H18: Numeric
A19: …... | B19: …... | C19: …... | D19: …... | E19: …... | F19: …... | G19: …... | H19: …...
A20: CEC | B20: 0 | C20: 5 | D20: very low | E20: 2 | F20: 85 | G20: 1 | H20: Numeric
A21: CEC | B21: 5 | C21: 15 | D21: low | E21: 3 | F21: 90 | G21: 2 | H21: Numeric
A22: CEC | B22: 15 | C22: 30 | D22: moderate | E22: 4 | F22: 95 | G22: 3 | H22: Numeric
A23: CEC | B23: 20 | C23: 999 | D23: high | E23: 5 | F23: 100 | G23: 4 | H23: Numeric
A24: ….... | B24: ….... | C24: ….... | D24: ….... | E24: ….... | F24: ….... | G24: ….... | H24: …....
A25: slope | B25: 0 | C25: 2 | D25: Level | E25: 5 | F25: 100 | G25: 1 | H25: Numeric
A26: slope | B26: 2 | C26: 5 | D26: Gently Sloping | E26: 4 | F26: 90 | G26: 2 | H26: Numeric
A27: slope | B27: 5 | C27: 10 | D27: Sloping | E27: 3 | F27: 80 | G27: 3 | H27: Numeric
A28: slope | B28: 10 | C28: 15 | D28: Strongly Sloping | E28: 2 | F28: 70 | G28: 4 | H28: Numeric
A29: slope | B29: 15 | C29: 999 | D29: Very Strongly Sloping | E29: 1 | F29: 60 | G29: 5 | H29: Numeric
A30: ….. | B30: ….. | C30: ….. | D30: ….. | E30: ….. | F30: ….. | G30: ….. | H30: …..
A31: Surface fragments | B31: 0.01 | C31: 1 | D31: stony | E31: 5 | F31: 100 | G31: 1 | H31: Numeric
A32: Surface fragments | B32: 1 | C32: 3 | D32: very stony | E32: 4 | F32: 95 | G32: 2 | H32: Numeric
A33: Surface fragments | B33: 3 | C33: 15 | D33: Extremely stony | E33: 3 | F33: 90 | G33: 3 | H33: Numeric
A34: Surface fragments | B34: 15 | C34: 50 | D34: Rubbly | E34: 2 | F34: 85 | G34: 4 | H34: Numeric
A35: Surface fragments | B35: 50 | C35: 999 | D35: Very rubbly | E35: 1 | F35: 80 | G35: 5 | H35: Numeric
A36: …. | B36: …. | C36: …. | D36: …. | E36: …. | F36: …. | G36: …. | H36: …...
A37: Hardpan layers | B37: 0 | C37: 0 | D37: Absent | E37: 5 | F37: 100 | G37: 1 | H37: Numeric
A38: Hardpan layers | B38: 100 | C38: 150 | D38: Moderately effective | E38: 4 | F38: 90 | G38: 2 | H38: Numeric
A39: Hardpan layers | B39: 50 | C39: 100 | D39: Strongly effective | E39: 3 | F39: 80 | G39: 3 | H39: Numeric
A40: Hardpan layers | B40: 0 | C40: 50 | D40: Not suitable | E40: 2 | F40: 70 | G40: 4 | H40: Numeric
...

Sheet assessment
A1: Indicator | B1: Input | C1: score | D1: Recommendation
A2: Ece | B2: 10 | C2: =LOOKUP(B2,{0,4,8,16,32},{100,95,90,85,80}) -> 90
A3: soil depth | B3: 110 | C3: =LOOKUP(B3,{0,25,60,90,120},{50,70,80,90,100}) -> 90
A4: texture | B4: loamy sand | C4: =VLOOKUP(B4,database!$D$51:$F$59,3,FALSE) -> 85
A5: CaCO3 | B5: 8 | C5: =LOOKUP(B5,{0,0.0001,2,10,25},{100,95,90,85,80}) -> 90
A6: CEC | B6: 7 | C6: =LOOKUP(B6,{0,5,15,20},{85,90,95,100}) -> 90
A7: Slope | B7: 1 | C7: =LOOKUP(B7,{0,2,5,10,15},{100,90,80,70,60}) -> 100
A8: ph | B8: 7.5 | C8: =LOOKUP(B8,{6.6,7.4,7.9,8.5},{100,95,90,85}) -> 95
A9: Surface fragments | B9: 0.1 | C9: =LOOKUP(B9,{0.01,1,3,15,50},{100,95,90,85,80}) -> 100
A10: Hardpan layers | B10: 150 | C10: =IF(B10>=150,100,IF(B10>=100,90,IF(B10>=50,80,70))) -> 100
A11: OM | B11: 2 | C11: =LOOKUP(B11,{0,0.75,1.5,3},{0,90,95,100}) -> 95
A12: Erosion | B12: 0 | C12: =IF(B12=0,100,LOOKUP(B12,{0.0001,25,75,100},{90,80,70,60})) -> 100
A13: Flooding | B13: No Flooding | C13: =VLOOKUP(B13,database!$D$67:$F$71,3,FALSE) -> 100
A14: Ndvi | B14: 0.3 | C14: =LOOKUP(B14,{0,0.2,0.4,0.6},{85,90,95,100}) -> 90
A15: Rainfall | B15: 150 | C15: =LOOKUP(B15,{0,100,300,600,1000},{80,85,90,95,100}) -> 85
A16: Evapotranspiration | B16: 200 | C16: =LOOKUP(B16,{0,60,120,180,240},{100,95,90,85,80}) -> 85
A17: Wind Speed | B17: 3 | C17: =LOOKUP(B17,{0,2,5,8},{100,95,90,85}) -> 95
A18: Temperature | B18: 25 | C18: =LOOKUP(B18,{0,15,25,40},{80,100,95,70}) -> 95
A19: proximity to roads | B19: Good asphalt road | C19: =VLOOKUP(B19,database!$D$100:$F$102,3,FALSE) -> 100
A20: Proximity to markets | B20: 15–30 km | C20: =VLOOKUP(B20,database!$D$104:$F$106,3,FALSE) -> 90
A21: Proximity to service centers | B21: No services available | C21: =VLOOKUP(B21,database!$D$108:$F$110,3,FALSE) -> 80
A22: Energy Availability | B22: Solar energy available | C22: =VLOOKUP(B22,database!$D$112:$F$115,3,FALSE) -> 95
A23: Water Availability | B23: Moderate groundwater availability | C23: =VLOOKUP(B23,database!$D$117:$F$121,3,FALSE) -> 90
A24: Water Quality | B24: 2 | C24: =LOOKUP(B24,{0,0.7,2,3},{100,90,80,70}) -> 80

Sheet results
A1: Indicator | B1: Score
A2: Ece | B2: =assessment!C2 -> 90
A3: soil depth | B3: =assessment!C3 -> 90
A4: texture | B4: =assessment!C4 -> 85
A5: CaCO3 | B5: =assessment!C5 -> 90
A6: CEC | B6: =assessment!C6 -> 90
A7: Slope | B7: =assessment!C7 -> 100
A8: ph | B8: =assessment!C8 -> 95
A9: Surface fragments | B9: =assessment!C9 -> 100
A10: Hardpan layers | B10: =assessment!C10 -> 100
A11: OM | B11: =assessment!C11 -> 95
A12: soil index | B12: =(B2/100)*(B3/100)*(B4/100)*(B5/100)*(B6/100)*(B7/100)*(B8/100)*(B9/100)*(B10/100)*(B11/100) -> 0.50331071
A13: Soil Rating | B13: =LOOKUP(B12,refrences!$C$2:$C$5,refrences!$A$2:$A$5) -> Moderate
A14: Erosion | B14: =assessment!C12 -> 100
A15: Flooding | B15: =assessment!C13 -> 100
A16: Ndvi | B16: =assessment!C14 -> 90
A17: protection index | B17: =B14/100*B15/100*B16/100 -> 0.9
A18: protection rating | B18: =LOOKUP(B17,refrences!$C$2:$C$5,refrences!$A$2:$A$5) -> High
A19: Rainfall | B19: =assessment!C15 -> 85
A20: Evapotranspiration | B20: =assessment!C16 -> 85
A21: Wind Speed | B21: =assessment!C17 -> 95
A22: Temperature | B22: =assessment!C18 -> 95
A23: climate index | B23: =B19/100*B20/100*B21/100*B22/100 -> 0.65205625
A24: climate rating | B24: =LOOKUP(B23,refrences!$C$2:$C$5,refrences!$A$2:$A$5) -> High
A25: proximity to roads | B25: =assessment!C19 -> 100
A26: Proximity to markets | B26: =assessment!C20 -> 90
A27: Proximity to service centers | B27: =assessment!C21 -> 80
A28: Energy Availability | B28: =assessment!C22 -> 95
A29: infrastructure index | B29: =B25/100*B26/100*B27/100*B28/100 -> 0.684
A30: infrastructure rating | B30: =LOOKUP(B29,refrences!$C$2:$C$5,refrences!$A$2:$A$5) -> High
A31: Water Availability | B31: =assessment!C23 -> 90
A32: Water Quality | B32: =assessment!C24 -> 80
A33: water index | B33: =B31/100*B32/100 -> 0.72
A34: water rating | B34: =LOOKUP(B33,refrences!$C$2:$C$5,refrences!$A$2:$A$5) -> High
A36: Overall Sustainability Index | B36: =B12*B17*B23*B29*B33 -> 0.14546293
A37: Overall Sustainability rating | B37: =LOOKUP(B36,refrences!$C$2:$C$5,refrences!$A$2:$A$5) -> Low
A39: Indicator | B39: Score
A40: soil index | B40: 0.36476782
A41: Soil Rating | B41: Moderate
A42: protection index | B42: 0.576
...

Sheet refrences
A1: Rating | B1: max | C1: min | D1: Class
A2: Very Low | B2: 0.1 | C2: 0 | D2: I
A3: Low | B3: 0.3 | C3: 0.1 | D3: II
A4: Moderate | B4: 0.6 | C4: 0.3 | D4: III
A5: High | B5: 1 | C5: 0.6 | D5: IV
